<?xml version="1.0" ?>
<!-- =================================================================================== -->
<!-- |    This document was autogenerated by xacro from ngeeann_av.xacro               | -->
<!-- |    EDITING THIS FILE BY HAND IS NOT RECOMMENDED                                 | -->
<!-- =================================================================================== -->
<robot name="ngeeann_av">
  <material name="silver">
    <color rgba="0.800 0.800 0.800 1.000"/>
  </material>
  <material name="darkgrey">
    <color rgba="0.20 0.20 0.220 1.000"/>
  </material>
  <transmission name="br_axle_tran">
    <type>transmission_interface/SimpleTransmission</type>
    <joint name="br_axle">
      <hardwareInterface>hardware_interface/EffortJointInterface</hardwareInterface>
    </joint>
    <actuator name="br_axle_actr">
      <hardwareInterface>hardware_interface/EffortJointInterface</hardwareInterface>
      <mechanicalReduction>1</mechanicalReduction>
    </actuator>
  </transmission>
  <transmission name="bl_axle_tran">
    <type>transmission_interface/SimpleTransmission</type>
    <joint name="bl_axle">
      <hardwareInterface>hardware_interface/EffortJointInterface</hardwareInterface>
    </joint>
    <actuator name="bl_axle_actr">
      <hardwareInterface>hardware_interface/EffortJointInterface</hardwareInterface>
      <mechanicalReduction>1</mechanicalReduction>
    </actuator>
  </transmission>
  <transmission name="fr_axle_tran">
    <type>transmission_interface/SimpleTransmission</type>
    <joint name="fr_axle">
      <hardwareInterface>hardware_interface/EffortJointInterface</hardwareInterface>
    </joint>
    <actuator name="fr_axle_actr">
      <hardwareInterface>hardware_interface/EffortJointInterface</hardwareInterface>
      <mechanicalReduction>1</mechanicalReduction>
    </actuator>
  </transmission>
  <transmission name="fl_axle_tran">
    <type>transmission_interface/SimpleTransmission</type>
    <joint name="fl_axle">
      <hardwareInterface>hardware_interface/EffortJointInterface</hardwareInterface>
    </joint>
    <actuator name="fl_axle_actr">
      <hardwareInterface>hardware_interface/EffortJointInterface</hardwareInterface>
      <mechanicalReduction>1</mechanicalReduction>
    </actuator>
  </transmission>
  <transmission name="r_steer_tran">
    <type>transmission_interface/SimpleTransmission</type>
    <joint name="r_steer">
      <hardwareInterface>hardware_interface/EffortJointInterface</hardwareInterface>
    </joint>
    <actuator name="r_steer_actr">
      <hardwareInterface>hardware_interface/EffortJointInterface</hardwareInterface>
      <mechanicalReduction>1</mechanicalReduction>
    </actuator>
  </transmission>
  <transmission name="l_steer_tran">
    <type>transmission_interface/SimpleTransmission</type>
    <joint name="l_steer">
      <hardwareInterface>hardware_interface/EffortJointInterface</hardwareInterface>
    </joint>
    <actuator name="l_steer_actr">
      <hardwareInterface>hardware_interface/EffortJointInterface</hardwareInterface>
      <mechanicalReduction>1</mechanicalReduction>
    </actuator>
  </transmission>
  <!-- <xacro:property name="body_color" value="Gazebo/Silver" /> -->
  <!-- Original plugin file
<gazebo>
  <plugin filename="libgazebo_ros_control.so" name="control"/>
</gazebo>  -->
  <gazebo>
    <plugin filename="libgazebo_ros_control.so" name="gazebo_ros_control">
      <legacyModeNS>true</legacyModeNS>
    </plugin>
  </gazebo>
  <gazebo reference="chassis_link">
    <material>Gazebo/White</material>
    <mu1>0.2</mu1>
    <mu2>0.2</mu2>
    <selfCollide>true</selfCollide>
    <gravity>true</gravity>
  </gazebo>
  <gazebo reference="spoiler_link">
    <material>Gazebo/DarkGrey</material>
    <mu1>0.2</mu1>
    <mu2>0.2</mu2>
    <selfCollide>true</selfCollide>
    <gravity>true</gravity>
  </gazebo>
  <gazebo reference="br_1">
    <material>Gazebo/DarkGrey</material>
    <mu1>1.7</mu1>
    <mu2>1.7</mu2>
    <selfCollide>true</selfCollide>
  </gazebo>
  <gazebo reference="bl_1">
    <material>Gazebo/DarkGrey</material>
    <mu1>1.7</mu1>
    <mu2>1.7</mu2>
    <selfCollide>true</selfCollide>
  </gazebo>
  <gazebo reference="fr_1">
    <material>Gazebo/DarkGrey</material>
    <mu1>1.7</mu1>
    <mu2>1.7</mu2>
    <selfCollide>true</selfCollide>
  </gazebo>
  <gazebo reference="fl_1">
    <material>Gazebo/DarkGrey</material>
    <mu1>1.1</mu1>
    <mu2>1.1</mu2>
    <selfCollide>true</selfCollide>
  </gazebo>
  <gazebo reference="r_steer_1">
    <material>Gazebo/DarkGrey</material>
    <mu1>0.2</mu1>
    <mu2>0.2</mu2>
    <selfCollide>true</selfCollide>
  </gazebo>
  <gazebo reference="l_steer_1">
    <material>Gazebo/DarkGrey</material>
    <mu1>0.2</mu1>
    <mu2>0.2</mu2>
    <selfCollide>true</selfCollide>
  </gazebo>
  <joint name="hokuyo_joint" type="fixed">
    <axis xyz="0 1 0"/>
    <origin rpy="0 0 1.5708" xyz="0 2.34 0.24"/>
    <parent link="chassis_link"/>
    <child link="hokuyo_link"/>
  </joint>
  <link name="hokuyo_link">
    <collision>
      <origin rpy="0 0 0" xyz="0 0 0"/>
      <geometry>
        <box size="0.05 0.05 0.05"/>
      </geometry>
    </collision>
    <visual>
      <origin rpy="0 0 0" xyz="0 0 0"/>
      <geometry>
        <mesh filename="package://ngeeann_av_description/meshes/hokuyo.dae"/>
      </geometry>
    </visual>
    <inertial>
      <mass value="1e-5"/>
      <origin rpy="0 0 0" xyz="0 0 0"/>
      <inertia ixx="1e-6" ixy="0" ixz="0" iyy="1e-6" iyz="0" izz="1e-6"/>
    </inertial>
  </link>
  <gazebo reference="hokuyo_link">
    <sensor name="head_hokuyo_sensor" type="ray">
      <pose>0 0 0 0 0 0</pose>
      <visualize>true</visualize>
      <update_rate>40</update_rate>
      <ray>
        <scan>
          <horizontal>
            <samples>720</samples>
            <resolution>1</resolution>
            <min_angle>-1.570796</min_angle>
            <max_angle>1.570796</max_angle>
          </horizontal>
        </scan>
        <range>
          <min>0.10</min>
          <max>30.0</max>
          <resolution>0.01</resolution>
        </range>
        <noise>
          <type>gaussian</type>
          <!-- Noise parameters based on published spec for Hokuyo laser
		             achieving "+-30mm" accuracy at range < 10m.  A mean of 0.0m and
		             stddev of 0.01m will put 99.7% of samples within 0.03m of the true
		             reading. -->
          <mean>0.0</mean>
          <stddev>0.01</stddev>
        </noise>
      </ray>
      <plugin filename="libgazebo_ros_laser.so" name="gazebo_ros_head_hokuyo_controller">
        <topicName>/laser/scan</topicName>
        <frameName>/hokuyo_link</frameName>
      </plugin>
    </sensor>
  </gazebo>
  <joint name="camera_joint" type="fixed">
    <axis xyz="0 0 0"/>
    <origin rpy="0 0 1.5708" xyz="0 2.45 0.07"/>
    <parent link="chassis_link"/>
    <child link="camera_link"/>
  </joint>
  <link name="camera_link">
    <collision>
      <origin rpy="0 0 0" xyz="0 0 0"/>
      <geometry>
        <box size="0.05 0.05 0.05"/>
      </geometry>
    </collision>
    <visual>
      <origin rpy="0 0 0" xyz="0 0 0"/>
      <geometry>
        <box size="0.05 0.05 0.05"/>
      </geometry>
      <material name="red">
        <color rgba="1 0 0 1"/>
      </material>
    </visual>
    <inertial>
      <mass value="1e-5"/>
      <origin rpy="0 0 0" xyz="0 0 0"/>
      <inertia ixx="1e-6" ixy="0" ixz="0" iyy="1e-6" iyz="0" izz="1e-6"/>
    </inertial>
  </link>
  <gazebo reference="camera_link">
    <mu1>0.2</mu1>
    <mu2>0.2</mu2>
    <material>Gazebo/Red</material>
  </gazebo>
  <gazebo reference="camera_link">
    <sensor name="camera1" type="camera">
      <update_rate>30.0</update_rate>
      <camera name="head">
        <horizontal_fov>1.3962634</horizontal_fov>
        <image>
          <width>800</width>
          <height>800</height>
          <format>R8G8B8</format>
        </image>
        <clip>
          <near>0.02</near>
          <far>300</far>
        </clip>
        <noise>
          <type>gaussian</type>
          <!-- Noise is sampled independently per pixel on each frame.  
		           That pixel's noise value is added to each of its color
		           channels, which at that point lie in the range [0,1]. -->
          <mean>0.0</mean>
          <stddev>0.007</stddev>
        </noise>
      </camera>
      <plugin filename="libgazebo_ros_camera.so" name="camera_controller">
        <alwaysOn>true</alwaysOn>
        <updateRate>0.0</updateRate>
        <cameraName>/rgbcamera</cameraName>
        <imageTopicName>image_raw</imageTopicName>
        <cameraInfoTopicName>camera_info</cameraInfoTopicName>
        <frameName>/camera_link</frameName>
        <hackBaseline>0.07</hackBaseline>
        <distortionK1>0.0</distortionK1>
        <distortionK2>0.0</distortionK2>
        <distortionK3>0.0</distortionK3>
        <distortionT1>0.0</distortionT1>
        <distortionT2>0.0</distortionT2>
      </plugin>
    </sensor>
  </gazebo>
  <link name="base_link"/>
  <joint name="base_link_joint" type="fixed">
    <origin rpy="0 0 0" xyz="0 0 0.46936"/>
    <parent link="base_link"/>
    <child link="chassis_link"/>
  </joint>
  <link name="chassis_link">
    <inertial>
      <origin rpy="0 0 0" xyz="1.04282e-06 0.07307 0.1816"/>
      <mass value="1580"/>
      <inertia ixx="1997.8579" ixy="-3e-05" ixz="-1e-06" iyy="442.7692" iyz="62.5206" izz="2238.0524"/>
    </inertial>
    <visual>
      <origin rpy="0 0 0" xyz="0 0 0"/>
      <geometry>
        <mesh filename="package://ngeeann_av_description/meshes/chassis_link.stl" scale="0.001 0.001 0.001"/>
      </geometry>
      <material name="silver"/>
    </visual>
    <collision>
      <origin rpy="0 0 0" xyz="0 0 0"/>
      <geometry>
        <mesh filename="package://ngeeann_av_description/meshes/chassis_link.stl" scale="0.001 0.001 0.001"/>
      </geometry>
    </collision>
  </link>
  <joint name="spoiler_joint" type="fixed">
    <origin rpy="1.5708 0 3.14159" xyz="0 0.05 -0.05"/>
    <parent link="chassis_link"/>
    <child link="spoiler_link"/>
  </joint>
  <link name="spoiler_link">
    <visual>
      <origin rpy="0 0 0" xyz="0 0 0"/>
      <geometry>
        <mesh filename="package://ngeeann_av_description/meshes/spoiler.stl" scale="0.001 0.001 0.001"/>
      </geometry>
      <material name="silver"/>
    </visual>
    <collision>
      <origin rpy="0 0 0" xyz="0 0 0"/>
      <geometry>
        <mesh filename="package://ngeeann_av_description/meshes/spoiler.stl" scale="0.001 0.001 0.001"/>
      </geometry>
    </collision>
  </link>
  <link name="br_1">
    <inertial>
      <origin rpy="0 0 0" xyz="-0.0377 1.5929e-07 -1.5929e-07"/>
      <mass value="24.5"/>
      <inertia ixx="1.845139" ixy="-0.0" ixz="-0.0" iyy="1.049606" iyz="0.0" izz="1.049606"/>
    </inertial>
    <visual>
      <origin rpy="0 0 0" xyz="-0.8750 1.0136 0.1444"/>
      <geometry>
        <mesh filename="package://ngeeann_av_description/meshes/br_1.stl" scale="0.001 0.001 0.001"/>
      </geometry>
      <material name="darkgrey"/>
    </visual>
    <collision>
      <origin rpy="0 0 0" xyz="-0.8750 1.0136 0.1444"/>
      <geometry>
        <mesh filename="package://ngeeann_av_description/meshes/br_1.stl" scale="0.001 0.001 0.001"/>
      </geometry>
    </collision>
  </link>
  <link name="bl_1">
    <inertial>
      <origin rpy="0 0 0" xyz="-0.0377 1.5929e-07 -1.5929e-07"/>
      <mass value="24.5"/>
      <inertia ixx="1.845139" ixy="-0.0" ixz="-0.0" iyy="1.049606" iyz="0.0" izz="1.049606"/>
    </inertial>
    <visual>
      <origin rpy="0 0 0" xyz="0.8750 1.0136 0.1444"/>
      <geometry>
        <mesh filename="package://ngeeann_av_description/meshes/bl_1.stl" scale="0.001 0.001 0.001"/>
      </geometry>
      <material name="darkgrey"/>
    </visual>
    <collision>
      <origin rpy="0 0 0" xyz="0.8750 1.0136 0.1444"/>
      <geometry>
        <mesh filename="package://ngeeann_av_description/meshes/bl_1.stl" scale="0.001 0.001 0.001"/>
      </geometry>
    </collision>
  </link>
  <link name="fr_1">
    <inertial>
      <origin rpy="0 0 0" xyz="-0.0377 1.5929e-07 -1.5929e-07"/>
      <mass value="24.5"/>
      <inertia ixx="1.845139" ixy="-0.0" ixz="-0.0" iyy="1.049606" iyz="0.0" izz="1.049606"/>
    </inertial>
    <visual>
      <origin rpy="0 0 0" xyz="-0.8750 -1.5174 0.1444"/>
      <geometry>
        <mesh filename="package://ngeeann_av_description/meshes/fr_1.stl" scale="0.001 0.001 0.001"/>
      </geometry>
      <material name="darkgrey"/>
    </visual>
    <collision>
      <origin rpy="0 0 0" xyz="-0.8750 -1.5174 0.1444"/>
      <geometry>
        <mesh filename="package://ngeeann_av_description/meshes/fr_1.stl" scale="0.001 0.001 0.001"/>
      </geometry>
    </collision>
  </link>
  <link name="fl_1">
    <inertial>
      <origin rpy="0 0 0" xyz="-0.0377 1.5929e-07 -1.5929e-07"/>
      <mass value="24.5"/>
      <inertia ixx="1.845139" ixy="-0.0" ixz="-0.0" iyy="1.049606" iyz="0.0" izz="1.049606"/>
    </inertial>
    <visual>
      <origin rpy="0 0 0" xyz="0.8750 -1.5174 0.1444"/>
      <geometry>
        <mesh filename="package://ngeeann_av_description/meshes/fl_1.stl" scale="0.001 0.001 0.001"/>
      </geometry>
      <material name="darkgrey"/>
    </visual>
    <collision>
      <origin rpy="0 0 0" xyz="0.8750 -1.5174 0.1444"/>
      <geometry>
        <mesh filename="package://ngeeann_av_description/meshes/fl_1.stl" scale="0.001 0.001 0.001"/>
      </geometry>
    </collision>
  </link>
  <link name="r_steer_1">
    <inertial>
      <origin rpy="0 0 0" xyz="0.003381 1.5929e-07 0.02162"/>
      <mass value="1"/>
      <inertia ixx="1.0" ixy="0.0" ixz="0.0" iyy="1.0" iyz="0.0" izz="1.0"/>
    </inertial>
  </link>
  <link name="l_steer_1">
    <inertial>
      <origin rpy="0 0 0" xyz="0.003381 1.5929e-07 0.02162"/>
      <mass value="1"/>
      <inertia ixx="1.0" ixy="0.0" ixz="0.0" iyy="1.0" iyz="0.0" izz="1.0"/>
    </inertial>
  </link>
  <joint name="br_axle" type="continuous">
    <origin rpy="0 0 0" xyz="0.8750 -1.013637 -0.144363"/>
    <parent link="chassis_link"/>
    <child link="br_1"/>
    <axis xyz="-1.0 0.0 0.0"/>
  </joint>
  <joint name="bl_axle" type="continuous">
    <origin rpy="0 0 0" xyz="-0.8750 -1.013637 -0.144363"/>
    <parent link="chassis_link"/>
    <child link="bl_1"/>
    <axis xyz="-1.0 0.0 0.0"/>
  </joint>
  <joint name="fr_axle" type="continuous">
    <origin rpy="0 0 0" xyz="0.05 0.0 0.0"/>
    <parent link="r_steer_1"/>
    <child link="fr_1"/>
    <axis xyz="-1.0 0.0 0.0"/>
  </joint>
  <joint name="fl_axle" type="continuous">
    <origin rpy="0 0 0" xyz="-0.05 0.0 0.0"/>
    <parent link="l_steer_1"/>
    <child link="fl_1"/>
    <axis xyz="-1.0 0.0 0.0"/>
  </joint>
  <joint name="r_steer" type="revolute">
    <origin rpy="0 0 0" xyz="0.8250 1.517363 -0.144363"/>
    <parent link="chassis_link"/>
    <child link="r_steer_1"/>
    <axis xyz="0.0 0.0 1.0"/>
    <dynamics damping="0.01" friction="0.01"/>
    <limit effort="1000.0" lower="-0.95" upper="0.95" velocity="100"/>
  </joint>
  <joint name="l_steer" type="revolute">
    <origin rpy="0 0 0" xyz="-0.8250 1.517363 -0.144363"/>
    <parent link="chassis_link"/>
    <child link="l_steer_1"/>
    <axis xyz="0.0 0.0 1.0"/>
    <dynamics damping="0.01" friction="0.01"/>
    <limit effort="1000.0" lower="-0.95" upper="0.95" velocity="100"/>
  </joint>
</robot>
